Workbook

Sheet Súhrn
A1: Porovnanie dotačných výziev ČR – grantové poradenstvo
A3: Dnes (stav sa prepočíta od tohto dátumu): | B3: 46290
A5: Stav \ Relevancia | B5: Vysoká | C5: Stredná | D5: Nízka | E5: Spolu
A6: Po uzávierke | B6: =COUNTIFS(Výzvy!$N$2:$N$117,$A6,Výzvy!$P$2:$P$117,B$5) -> 0 | C6: =COUNTIFS(Výzvy!$N$2:$N$117,$A6,Výzvy!$P$2:$P$117,C$5) -> 0 | D6: =COUNTIFS(Výzvy!$N$2:$N$117,$A6,Výzvy!$P$2:$P$117,D$5) -> 11 | E6: =SUM(B6:D6) -> 11
A7: Končí do 14 dní | B7: =COUNTIFS(Výzvy!$N$2:$N$117,$A7,Výzvy!$P$2:$P$117,B$5) -> 1 | C7: =COUNTIFS(Výzvy!$N$2:$N$117,$A7,Výzvy!$P$2:$P$117,C$5) -> 1 | D7: =COUNTIFS(Výzvy!$N$2:$N$117,$A7,Výzvy!$P$2:$P$117,D$5) -> 21 | E7: =SUM(B7:D7) -> 23
A8: Otvorená | B8: =COUNTIFS(Výzvy!$N$2:$N$117,$A8,Výzvy!$P$2:$P$117,B$5) -> 13 | C8: =COUNTIFS(Výzvy!$N$2:$N$117,$A8,Výzvy!$P$2:$P$117,C$5) -> 14 | D8: =COUNTIFS(Výzvy!$N$2:$N$117,$A8,Výzvy!$P$2:$P$117,D$5) -> 23 | E8: =SUM(B8:D8) -> 50
A9: Očakávaná | B9: =COUNTIFS(Výzvy!$N$2:$N$117,$A9,Výzvy!$P$2:$P$117,B$5) -> 3 | C9: =COUNTIFS(Výzvy!$N$2:$N$117,$A9,Výzvy!$P$2:$P$117,C$5) -> 6 | D9: =COUNTIFS(Výzvy!$N$2:$N$117,$A9,Výzvy!$P$2:$P$117,D$5) -> 6 | E9: =SUM(B9:D9) -> 15
A10: Priebežná | B10: =COUNTIFS(Výzvy!$N$2:$N$117,$A10,Výzvy!$P$2:$P$117,B$5) -> 0 | C10: =COUNTIFS(Výzvy!$N$2:$N$117,$A10,Výzvy!$P$2:$P$117,C$5) -> 5 | D10: =COUNTIFS(Výzvy!$N$2:$N$117,$A10,Výzvy!$P$2:$P$117,D$5) -> 12 | E10: =SUM(B10:D10) -> 17
A11: Spolu | B11: =SUM(B6:B10) -> 17 | C11: =SUM(C6:C10) -> 26 | D11: =SUM(D6:D10) -> 73 | E11: =SUM(B11:D11) -> 116
A13: Zdroj \ Stav | B13: Po uzávierke | C13: Končí do 14 dní | D13: Otvorená | E13: Očakávaná | F13: Priebežná | G13: Spolu
A14: Tvoj zoznam | B14: =COUNTIFS(Výzvy!$B$2:$B$117,$A14,Výzvy!$N$2:$N$117,B$13) -> 11 | C14: =COUNTIFS(Výzvy!$B$2:$B$117,$A14,Výzvy!$N$2:$N$117,C$13) -> 23 | D14: =COUNTIFS(Výzvy!$B$2:$B$117,$A14,Výzvy!$N$2:$N$117,D$13) -> 40 | E14: =COUNTIFS(Výzvy!$B$2:$B$117,$A14,Výzvy!$N$2:$N$117,E$13) -> 14 | F14: =COUNTIFS(Výzvy!$B$2:$B$117,$A14,Výzvy!$N$2:$N$117,F$13) -> 17 | G14: =SUM(B14:F14) -> 105
A15: Doplnok (web) | B15: =COUNTIFS(Výzvy!$B$2:$B$117,$A15,Výzvy!$N$2:$N$117,B$13) -> 0 | C15: =COUNTIFS(Výzvy!$B$2:$B$117,$A15,Výzvy!$N$2:$N$117,C$13) -> 0 | D15: =COUNTIFS(Výzvy!$B$2:$B$117,$A15,Výzvy!$N$2:$N$117,D$13) -> 10 | E15: =COUNTIFS(Výzvy!$B$2:$B$117,$A15,Výzvy!$N$2:$N$117,E$13) -> 1 | F15: =COUNTIFS(Výzvy!$B$2:$B$117,$A15,Výzvy!$N$2:$N$117,F$13) -> 0 | G15: =SUM(B15:F15) -> 11
A16: Spolu | B16: =SUM(B14:B15) -> 11 | C16: =SUM(C14:C15) -> 23 | D16: =SUM(D14:D15) -> 50 | E16: =SUM(E14:E15) -> 15 | F16: =SUM(F14:F15) -> 17 | G16: =SUM(B16:F16) -> 116
A18: Oplatí sa riešiť hneď (vysoká relevancia, ešte sa dá podať)
A19: Počet: | B19: =COUNTIFS(Výzvy!$P$2:$P$117,"Vysoká",Výzvy!$N$2:$N$117,"<>Po uzávierke") -> 17

Sheet Výzvy
A1: ID | B1: Zdroj | C1: Poskytovateľ / program | D1: Výzva | E1: Pre koho | F1: Typ financovania | G1: Územie | H1: Alokácia | I1: Max. % | J1: Max. dotácia | K1: Uzávierka | L1: Termín – poznámka | M1: Status v zdroji | N1: Stav k dátumu | O1: Dní do uzávierky | P1: Relevancia pre poradenstvo | Q1: Poznámka | R1: Overenie / zdroj
A2: 18 | B2: Tvoj zoznam | C2: OP Životní prostředí | D2: 104. výzva – prírode blízke opatrenia v krajine a sídlach | E2: Mix (obce, firmy, NNO, FO) | F2: Grant | G2: Regionálne (Praha + prechodové regióny) | H2: 330 000 000 Kč | I2: 100 % | J2: neuvedené | K2: 46290 | M2: Otvorená | N2: =IF(K2="",M2,IF(K2<Súhrn!$B$3,"Po uzávierke",IF(M2="Očakávaná","Očakávaná",IF(K2-Súhrn!$B$3<=14,"Končí do 14 dní","Otvorená")))) -> Končí do 14 dní | O2: =IF(K2="","",K2-Súhrn!$B$3) -> 0 | P2: Vysoká | Q2: Uzávierka dnes. | R2: tvoj zoznam
A3: 44 | B3: Tvoj zoznam | C3: TA ČR – SIGMA | D3: 18. verejná súťaž – DC1 komercializácia VaVaI+ | E3: Malé podniky a startupy | F3: Grant | G3: Celorepublikové | H3: 10 000 000 Kč | I3: 70 % | J3: 730 000 Kč | K3: 46322 | M3: Otvorená | N3: =IF(K3="",M3,IF(K3<Súhrn!$B$3,"Po uzávierke",IF(M3="Očakávaná","Očakávaná",IF(K3-Súhrn!$B$3<=14,"Končí do 14 dní","Otvorená")))) -> Otvorená | O3: =IF(K3="","",K3-Súhrn!$B$3) -> 32 | P3: Vysoká | Q3: Výstupom je štúdia uskutočniteľnosti v angličtine – ideálne na spracovanie konzultantom. | R3: tvoj zoznam
A4: 46 | B4: Tvoj zoznam | C4: AOPK ČR – OPŽP | D4: 17. výzva SC 1.3 – prírode blízke opatrenia | E4: Mix (obce, vlastníci pozemkov, firmy, NNO) | F4: Grant | G4: Celorepublikové | H4: 275 000 000 Kč | I4: 100 % | J4: neuvedené | K4: 46325 | M4: Otvorená | N4: =IF(K4="",M4,IF(K4<Súhrn!$B$3,"Po uzávierke",IF(M4="Očakávaná","Očakávaná",IF(K4-Súhrn!$B$3<=14,"Končí do 14 dní","Otvorená")))) -> Otvorená | O4: =IF(K4="","",K4-Súhrn!$B$3) -> 35 | P4: Vysoká | Q4: Široký okruh žiadateľov, 100 %. | R4: tvoj zoznam
A5: 47 | B5: Tvoj zoznam | C5: AOPK ČR – OPŽP | D5: 18. výzva SC 1.6 – biodiverzita, chránené územia | E5: Mix (obce, vlastníci pozemkov, firmy, NNO) | F5: Grant | G5: Celorepublikové | H5: 75 000 000 Kč | I5: 100 % | J5: neuvedené | K5: 46325 | M5: Otvorená | N5: =IF(K5="",M5,IF(K5<Súhrn!$B$3,"Po uzávierke",IF(M5="Očakávaná","Očakávaná",IF(K5-Súhrn!$B$3<=14,"Končí do 14 dní","Otvorená")))) -> Otvorená | O5: =IF(K5="","",K5-Súhrn!$B$3) -> 35 | P5: Vysoká | R5: tvoj zoznam
A6: 48 | B6: Tvoj zoznam | C6: Hl. m. Praha | D6: Památková péče 2027 – vlastníci pamiatkovo významných objektov | E6: Vlastníci pamiatok (Praha) | F6: Grant | G6: Regionálne | H6: 47 800 000 Kč | I6: 65 % | J6: 5 000 000 Kč | K6: 46325 | M6: Otvorená | N6: =IF(K6="",M6,IF(K6<Súhrn!$B$3,"Po uzávierke",IF(M6="Očakávaná","Očakávaná",IF(K6-Súhrn!$B$3<=14,"Končí do 14 dní","Otvorená")))) -> Otvorená | O6: =IF(K6="","",K6-Súhrn!$B$3) -> 35 | P6: Vysoká | R6: tvoj zoznam
A7: 107 | B7: Doplnok (web) | C7: Kraj Vysočina | D7: Podnikateľské vouchery 2026 | E7: Firmy a OSVČ na Vysočine | F7: Grant | G7: Regionálne | H7: 7 000 000 Kč | I7: neuvedené | J7: neuvedené | K7: 46325 | L7: príjem od 23. 3. 2026 | M7: Otvorená | N7: =IF(K7="",M7,IF(K7<Súhrn!$B$3,"Po uzávierke",IF(M7="Očakávaná","Očakávaná",IF(K7-Súhrn!$B$3<=14,"Končí do 14 dní","Otvorená")))) -> Otvorená | O7: =IF(K7="","",K7-Súhrn!$B$3) -> 35 | P7: Vysoká | Q7: Inovácie, digitalizácia, kyberbezpečnosť. | R7: https://www.businessinfo.cz/clanky/kraj-vysocina-vyhlasil-podnikatelske-vouchery-2026/
A8: 3 | B8: Tvoj zoznam | C8: Česká rozvojová agentura | D8: Program B2B – rozvojové partnerstvo pre súkromný sektor | E8: Firmy (obchodné korporácie) | F8: Grant | G8: Nadnárodné | H8: neuvedené | I8: 50 % | J8: 2 000 000 Kč | K8: 46336 | M8: Otvorená | N8: =IF(K8="",M8,IF(K8<Súhrn!$B$3,"Po uzávierke",IF(M8="Očakávaná","Očakávaná",IF(K8-Súhrn!$B$3<=14,"Končí do 14 dní","Otvorená")))) -> Otvorená | O8: =IF(K8="","",K8-Súhrn!$B$3) -> 46 | P8: Vysoká | Q8: Výstupom je štúdia uskutočniteľnosti/podnikateľský plán – typická konzultantská práca. | R8: tvoj zoznam
A9: 58 | B9: Tvoj zoznam | C9: OP Zaměstnanost+ | D9: 12. výzva SC 1.2 – diverzitná a flexibilná pracovná kultúra | E9: Firmy, OSVČ, NNO, obce | F9: Grant | G9: Celorepublikové | H9: 360 000 000 Kč | I9: 100 % | J9: 10 000 000 Kč | K9: 46356 | M9: Otvorená | N9: =IF(K9="",M9,IF(K9<Súhrn!$B$3,"Po uzávierke",IF(M9="Očakávaná","Očakávaná",IF(K9-Súhrn!$B$3<=14,"Končí do 14 dní","Otvorená")))) -> Otvorená | O9: =IF(K9="","",K9-Súhrn!$B$3) -> 66 | P9: Vysoká | Q9: 100 % financovanie mäkkých projektov, široký okruh žiadateľov. | R9: tvoj zoznam
A10: 110 | B10: Doplnok (web) | C10: Modernizační fond (SFŽP) | D10: TRANSCom 2/2025 – bezemisná cestná nákladná doprava | E10: Cestní dopravcovia | F10: Grant | G10: Celorepublikové | H10: 960 000 000 Kč | I10: neuvedené | J10: neuvedené | K10: 46356 | L10: príjem od 2. 2. 2026 | M10: Otvorená | N10: =IF(K10="",M10,IF(K10<Súhrn!$B$3,"Po uzávierke",IF(M10="Očakávaná","Očakávaná",IF(K10-Súhrn!$B$3<=14,"Končí do 14 dní","Otvorená")))) -> Otvorená | O10: =IF(K10="","",K10-Súhrn!$B$3) -> 66 | P10: Vysoká | Q10: Výmena dieselových nákladných áut za elektrické. | R10: https://sfzp.gov.cz/dotace-a-pujcky/modernizacni-fond/vyzvy/
A11: 112 | B11: Doplnok (web) | C11: Modernizační fond (SFŽP) | D11: RES+ 6/2025 – agrofotovoltika a úložiská | E11: Poľnohospodári | F11: Grant | G11: Celorepublikové | H11: 300 000 000 Kč | I11: neuvedené | J11: neuvedené | K11: 46568 | L11: príjem od 15. 1. 2026 | M11: Otvorená | N11: =IF(K11="",M11,IF(K11<Súhrn!$B$3,"Po uzávierke",IF(M11="Očakávaná","Očakávaná",IF(K11-Súhrn!$B$3<=14,"Končí do 14 dní","Otvorená")))) -> Otvorená | O11: =IF(K11="","",K11-Súhrn!$B$3) -> 278 | P11: Vysoká | R11: https://sfzp.gov.cz/dotace-a-pujcky/modernizacni-fond/vyzvy/
A12: 106 | B12: Doplnok (web) | C12: OP TAK (MPO/API) | D12: Technologie pro MAS (CLLD) – výzva II | E12: MSP na území MAS (mimo Prahy a miest nad 25 tis.) | F12: Grant | G12: Regionálne (MAS) | H12: 540 000 000 Kč | I12: neuvedené | J12: 1 490 000 Kč | K12: 46631 | L12: príjem od 1. 9. 2026 | M12: Otvorená | N12: =IF(K12="",M12,IF(K12<Súhrn!$B$3,"Po uzávierke",IF(M12="Očakávaná","Očakávaná",IF(K12-Súhrn!$B$3<=14,"Končí do 14 dní","Otvorená")))) -> Otvorená | O12: =IF(K12="","",K12-Súhrn!$B$3) -> 341 | P12: Vysoká | Q12: Podporuje aj softvér a IT infraštruktúru – ERP/Odoo. | R12: https://www.businessinfo.cz/clanky/op-tak-vyhlaseni-vyzvy-ii-technologie-pro-mas-clld/
A13: 105 | B13: Tvoj zoznam | C13: OP Zaměstnanost+ | D13: 92. výzva – detské skupiny (5) | E13: Firmy (podnikové DS), obce, NNO | F13: Grant | G13: Celorepublikové | H13: 300 000 000 Kč | I13: 100 % | J13: 7 882 992 Kč | K13: 46721 | L13: vyhlásenie 03/2027 | M13: Očakávaná | N13: =IF(K13="",M13,IF(K13<Súhrn!$B$3,"Po uzávierke",IF(M13="Očakávaná","Očakávaná",IF(K13-Súhrn!$B$3<=14,"Končí do 14 dní","Otvorená")))) -> Očakávaná | O13: =IF(K13="","",K13-Súhrn!$B$3) -> 431 | P13: Vysoká | Q13: Aj podnikové detské skupiny; 100 %. | R13: tvoj zoznam
A14: 71 | B14: Tvoj zoznam | C14: SFŽP ČR – NZÚ | D14: HOUSEnerg bytové domy – C: zdroje energie | E14: SVJ, bytové družstvá, vlastníci BD | F14: Grant | G14: Celorepublikové | H14: neuvedené | I14: 50 % | J14: neuvedené | K14: 46934 | M14: Otvorená | N14: =IF(K14="",M14,IF(K14<Súhrn!$B$3,"Po uzávierke",IF(M14="Očakávaná","Očakávaná",IF(K14-Súhrn!$B$3<=14,"Končí do 14 dní","Otvorená")))) -> Otvorená | O14: =IF(K14="","",K14-Súhrn!$B$3) -> 644 | P14: Vysoká | Q14: Veľký trh SVJ, dlhý termín. | R14: tvoj zoznam
A15: 72 | B15: Tvoj zoznam | C15: SFŽP ČR – NZÚ | D15: HOUSEnerg bytové domy – D: adaptačné a mitigačné opatrenia | E15: SVJ, bytové družstvá, vlastníci BD | F15: Grant | G15: Celorepublikové | H15: neuvedené | I15: 50 % | J15: neuvedené | K15: 46934 | M15: Otvorená | N15: =IF(K15="",M15,IF(K15<Súhrn!$B$3,"Po uzávierke",IF(M15="Očakávaná","Očakávaná",IF(K15-Súhrn!$B$3<=14,"Končí do 14 dní","Otvorená")))) -> Otvorená | O15: =IF(K15="","",K15-Súhrn!$B$3) -> 644 | P15: Vysoká | R15: tvoj zoznam
A16: 73 | B16: Tvoj zoznam | C16: SFŽP ČR – NZÚ | D16: HOUSEnerg bytové domy – A: zateplenie | E16: SVJ, bytové družstvá, vlastníci BD | F16: Grant | G16: Celorepublikové | H16: neuvedené | I16: 50 % | J16: neuvedené | K16: 46934 | M16: Otvorená | N16: =IF(K16="",M16,IF(K16<Súhrn!$B$3,"Po uzávierke",IF(M16="Očakávaná","Očakávaná",IF(K16-Súhrn!$B$3<=14,"Končí do 14 dní","Otvorená")))) -> Otvorená | O16: =IF(K16="","",K16-Súhrn!$B$3) -> 644 | P16: Vysoká | R16: tvoj zoznam
A17: 95 | B17: Tvoj zoznam | C17: OP Doprava | D17: 46. výzva – rýchlodobíjanie osobných áut, celá ČR | E17: Vlastníci/správcovia infraštruktúry (aj firmy) | F17: Grant | G17: Celorepublikové | H17: 315 000 000 Kč | I17: 55 % | J17: neuvedené | L17: vyhlásenie 09/2026, koniec 12/2026 | M17: Očakávaná | N17: =IF(K17="",M17,IF(K17<Súhrn!$B$3,"Po uzávierke",IF(M17="Očakávaná","Očakávaná",IF(K17-Súhrn!$B$3<=14,"Končí do 14 dní","Otvorená")))) -> Očakávaná | O17: =IF(K17="","",K17-Súhrn!$B$3) | P17: Vysoká | Q17: Aj pre firmy (obchody, hotely) s verejným prístupom. | R17: tvoj zoznam
A18: 97 | B18: Tvoj zoznam | C18: OP Doprava | D18: 47. výzva – rýchlodobíjanie nákladných vozidiel | E18: Vlastníci/správcovia infraštruktúry (aj firmy) | F18: Grant | G18: Celorepublikové | H18: 500 000 000 Kč | I18: 80 % | J18: neuvedené | L18: vyhlásenie 10/2026, koniec 01/2027 | M18: Očakávaná | N18: =IF(K18="",M18,IF(K18<Súhrn!$B$3,"Po uzávierke",IF(M18="Očakávaná","Očakávaná",IF(K18-Súhrn!$B$3<=14,"Končí do 14 dní","Otvorená")))) -> Očakávaná | O18: =IF(K18="","",K18-Súhrn!$B$3) | P18: Vysoká | R18: tvoj zoznam
A19: 27 | B19: Tvoj zoznam | C19: MK ČR | D19: Program záchrany architektonického dedičstva | E19: Vlastníci pamiatok | F19: Grant | G19: Celorepublikové | H19: neuvedené | I19: neuvedené | J19: neuvedené | K19: 46295 | M19: Otvorená | N19: =IF(K19="",M19,IF(K19<Súhrn!$B$3,"Po uzávierke",IF(M19="Očakávaná","Očakávaná",IF(K19-Súhrn!$B$3<=14,"Končí do 14 dní","Otvorená")))) -> Končí do 14 dní | O19: =IF(K19="","",K19-Súhrn!$B$3) -> 5 | P19: Stredná | Q19: Uzávierka o 5 dní. | R19: tvoj zoznam
A20: 1 | B20: Tvoj zoznam | C20: Hl. m. Praha | D20: Cestovný ruch 2027 – Opatření I (asociačné kongresy a konferencie) | E20: Organizátori kongresov | F20: Grant | G20: Regionálne | H20: 13 660 000 Kč | I20: 100 % | J20: 2 000 000 Kč | K20: 46307 | M20: Otvorená | N20: =IF(K20="",M20,IF(K20<Súhrn!$B$3,"Po uzávierke",IF(M20="Očakávaná","Očakávaná",IF(K20-Súhrn!$B$3<=14,"Končí do 14 dní","Otvorená")))) -> Otvorená | O20: =IF(K20="","",K20-Súhrn!$B$3) -> 17 | P20: Stredná | Q20: Úzka cieľová skupina (min. 300/700 účastníkov, 30–40 % zo zahraničia); krátky termín. | R20: tvoj zoznam
A21: 2 | B21: Tvoj zoznam | C21: Hl. m. Praha | D21: Cestovný ruch 2027 – Opatření II (akcie celoštátneho/medzinár. významu) | E21: Organizátori podujatí | F21: Grant | G21: Regionálne | H21: 9 000 000 Kč | I21: 30 % | J21: 2 000 000 Kč | K21: 46307 | L21: II.A max 2 mil. Kč, II.B max 0,5 mil. Kč | M21: Otvorená | N21: =IF(K21="",M21,IF(K21<Súhrn!$B$3,"Po uzávierke",IF(M21="Očakávaná","Očakávaná",IF(K21-Súhrn!$B$3<=14,"Končí do 14 dní","Otvorená")))) -> Otvorená | O21: =IF(K21="","",K21-Súhrn!$B$3) -> 17 | P21: Stredná | Q21: Akcie mimo centra/sezóny; nízka miera podpory (30 %). | R21: tvoj zoznam
A22: 116 | B22: Doplnok (web) | C22: SZIF – SP SZP | D22: Projektové intervencie – kolo 1.–22. 10. 2026 | E22: Poľnohospodári, spracovatelia | F22: Grant | G22: Celorepublikové | H22: neuvedené | I22: neuvedené | J22: neuvedené | K22: 46317 | L22: príjem 1.–22. 10. 2026; intervencie overiť (33.73 až jar 2027) | M22: Očakávaná | N22: =IF(K22="",M22,IF(K22<Súhrn!$B$3,"Po uzávierke",IF(M22="Očakávaná","Očakávaná",IF(K22-Súhrn!$B$3<=14,"Končí do 14 dní","Otvorená")))) -> Očakávaná | O22: =IF(K22="","",K22-Súhrn!$B$3) -> 27 | P22: Stredná | Q22: Ktoré intervencie sú v kole – overiť na szif.gov.cz. | R22: https://agro-svet.cz/dotace/kalendar-kol/
A23: 111 | B23: Doplnok (web) | C23: Modernizační fond (SFŽP) | D23: Železničná nákladná doprava – nové elektrické lokomotívy | E23: Železniční nákladní dopravcovia | F23: Grant | G23: Celorepublikové | H23: 3 500 000 000 Kč | I23: neuvedené | J23: neuvedené | K23: 46325 | L23: príjem od 15. 12. 2025 | M23: Otvorená | N23: =IF(K23="",M23,IF(K23<Súhrn!$B$3,"Po uzávierke",IF(M23="Očakávaná","Očakávaná",IF(K23-Súhrn!$B$3<=14,"Končí do 14 dní","Otvorená")))) -> Otvorená | O23: =IF(K23="","",K23-Súhrn!$B$3) -> 35 | P23: Stredná | R23: https://sfzp.gov.cz/dotace-a-pujcky/modernizacni-fond/vyzvy/
A24: 98 | B24: Tvoj zoznam | C24: Hl. m. Praha | D24: Životné prostredie 2027 – VII. adaptácia a mitigácia | E24: Mix (Praha: NNO, SVJ, FO) | F24: Grant | G24: Regionálne | H24: 11 250 000 Kč | I24: 100 % | J24: 600 000 Kč | K24: 46331 | M24: Očakávaná | N24: =IF(K24="",M24,IF(K24<Súhrn!$B$3,"Po uzávierke",IF(M24="Očakávaná","Očakávaná",IF(K24-Súhrn!$B$3<=14,"Končí do 14 dní","Otvorená")))) -> Očakávaná | O24: =IF(K24="","",K24-Súhrn!$B$3) -> 41 | P24: Stredná | R24: tvoj zoznam
A25: 50 | B25: Tvoj zoznam | C25: OP Životní prostředí | D25: 72. výzva – ekologické záťaže | E25: Mix (obce, firmy, štát) | F25: Grant | G25: Celorepublikové | H25: 1 700 000 000 Kč | I25: 85 % | J25: neuvedené | K25: 46336 | M25: Otvorená | N25: =IF(K25="",M25,IF(K25<Súhrn!$B$3,"Po uzávierke",IF(M25="Očakávaná","Očakávaná",IF(K25-Súhrn!$B$3<=14,"Končí do 14 dní","Otvorená")))) -> Otvorená | O25: =IF(K25="","",K25-Súhrn!$B$3) -> 46 | P25: Stredná | Q25: Vyžaduje analýzu rizík – špecializované. | R25: tvoj zoznam
A26: 57 | B26: Tvoj zoznam | C26: NPO – MŽP | D26: Renovačný pas budovy a dotačné poradenstvo (výzva 2/2026) | E26: Poradcovia (evidencia SFŽP) | F26: Grant | G26: Celorepublikové | H26: 200 000 000 Kč | I26: neuvedené | J26: 8 000 Kč | K26: 46356 | M26: Otvorená | N26: =IF(K26="",M26,IF(K26<Súhrn!$B$3,"Po uzávierke",IF(M26="Očakávaná","Očakávaná",IF(K26-Súhrn!$B$3<=14,"Končí do 14 dní","Otvorená")))) -> Otvorená | O26: =IF(K26="","",K26-Súhrn!$B$3) -> 66 | P26: Stredná | Q26: Dotácia priamo pre poradcov – vyžaduje registráciu v evidencii SFŽP. | R26: tvoj zoznam
A27: 59 | B27: Tvoj zoznam | C27: EK – EIC | D27: HORIZON-EIC-2026-ACCELERATOR-01 – EIC Accelerator | E27: MSP a startupy (deep-tech, TRL 5+) | F27: Grant + kapitál | G27: Nadnárodné | H27: neuvedené | I27: neuvedené | J27: neuvedené | K27: 46373 | M27: Otvorená | N27: =IF(K27="",M27,IF(K27<Súhrn!$B$3,"Po uzávierke",IF(M27="Očakávaná","Očakávaná",IF(K27-Súhrn!$B$3<=14,"Končí do 14 dní","Otvorená")))) -> Otvorená | O27: =IF(K27="","",K27-Súhrn!$B$3) -> 83 | P27: Stredná | Q27: Vysoká konkurencia, špecializované písanie. | R27: tvoj zoznam
A28: 60 | B28: Tvoj zoznam | C28: OP Životní prostředí | D28: 106. výzva – obnova stability svahov | E28: Obce, vlastníci, NNO | F28: Grant | G28: Celorepublikové | H28: 100 000 000 Kč | I28: 80 % | J28: neuvedené | K28: 46373 | M28: Otvorená | N28: =IF(K28="",M28,IF(K28<Súhrn!$B$3,"Po uzávierke",IF(M28="Očakávaná","Očakávaná",IF(K28-Súhrn!$B$3<=14,"Končí do 14 dní","Otvorená")))) -> Otvorená | O28: =IF(K28="","",K28-Súhrn!$B$3) -> 83 | P28: Stredná | R28: tvoj zoznam
A29: 61 | B29: Tvoj zoznam | C29: NPO – MMR a NRB | D29: Dostupné nájomné bývanie – výzva I | E29: Obce, developeri (projekty nad 250 mil. Kč) | F29: Zvýhodnený úver | G29: Celorepublikové | H29: 2 250 000 000 Kč | I29: 80 % | J29: 1 200 000 000 Kč | K29: 46387 | M29: Otvorená | N29: =IF(K29="",M29,IF(K29<Súhrn!$B$3,"Po uzávierke",IF(M29="Očakávaná","Očakávaná",IF(K29-Súhrn!$B$3<=14,"Končí do 14 dní","Otvorená")))) -> Otvorená | O29: =IF(K29="","",K29-Súhrn!$B$3) -> 97 | P29: Stredná | Q29: Veľké projekty. | R29: tvoj zoznam
A30: 108 | B30: Doplnok (web) | C30: IROP (MMR) | D30: 10. výzva eGovernment a kyberbezpečnosť (SC 1.1, VRR = Praha) | E30: Verejná správa (Praha) | F30: Grant | G30: Regionálne | H30: neuvedené | I30: neuvedené | J30: neuvedené | K30: 46387 | L30: predĺžené z 28. 5. 2026 | M30: Otvorená | N30: =IF(K30="",M30,IF(K30<Súhrn!$B$3,"Po uzávierke",IF(M30="Očakávaná","Očakávaná",IF(K30-Súhrn!$B$3<=14,"Končí do 14 dní","Otvorená")))) -> Otvorená | O30: =IF(K30="","",K30-Súhrn!$B$3) -> 97 | P30: Stredná | Q30: Overiť na irop.gov.cz. | R30: https://irop.gov.cz/cs/vyzvy-2021-2027
A31: 115 | B31: Doplnok (web) | C31: OP Spravedlivá transformace | D31: Transformačný úver | E31: Firmy (Karlovarský, Ústecký, Moravskosliezsky kraj) | F31: Zvýhodnený úver | G31: Regionálne | H31: neuvedené | I31: neuvedené | J31: neuvedené | K31: 46387 | L31: priebežne do konca 2026 | M31: Otvorená | N31: =IF(K31="",M31,IF(K31<Súhrn!$B$3,"Po uzávierke",IF(M31="Očakávaná","Očakávaná",IF(K31-Súhrn!$B$3<=14,"Končí do 14 dní","Otvorená")))) -> Otvorená | O31: =IF(K31="","",K31-Súhrn!$B$3) -> 97 | P31: Stredná | R31: https://opst.cz/aktualizovany-harmonogram-vyzev-opst-zkontrolujte-terminy-nektere-vyzvy-brzy-konci/
A32: 67 | B32: Tvoj zoznam | C32: EK – JTM | D32: JTM-2026-PSLF – úvery pre verejný sektor (2 výzvy) | E32: Verejný sektor (uhoľné regióny) | F32: Grant + úver EIB | G32: Nadnárodné | H32: €630 mil. | I32: neuvedené | J32: neuvedené | K32: 46434 | L32: Priebežné uzávierky; ďalšia 16. 2. 2027 | M32: Otvorená | N32: =IF(K32="",M32,IF(K32<Súhrn!$B$3,"Po uzávierke",IF(M32="Očakávaná","Očakávaná",IF(K32-Súhrn!$B$3<=14,"Končí do 14 dní","Otvorená")))) -> Otvorená | O32: =IF(K32="","",K32-Súhrn!$B$3) -> 144 | P32: Stredná | Q32: Pre obce/kraje v regiónoch spravodlivej transformácie. | R32: tvoj zoznam
A33: 74 | B33: Tvoj zoznam | C33: SFŽP ČR – NZÚ | D33: HOUSEnerg bytové domy – B: novostavba | E33: Stavebníci/prví nadobúdatelia BD | F33: Grant | G33: Celorepublikové | H33: neuvedené | I33: 50 % | J33: 150 000 Kč / byt (fix) | K33: 46934 | M33: Otvorená | N33: =IF(K33="",M33,IF(K33<Súhrn!$B$3,"Po uzávierke",IF(M33="Očakávaná","Očakávaná",IF(K33-Súhrn!$B$3<=14,"Končí do 14 dní","Otvorená")))) -> Otvorená | O33: =IF(K33="","",K33-Súhrn!$B$3) -> 644 | P33: Stredná | R33: tvoj zoznam
A34: 75 | B34: Tvoj zoznam | C34: SZP 2023–2027 | D34: 54.78 Podpora poradenstva – a) individuálne poradenstvo (záznam 11. 9. 2026) | E34: Poradcovia certifikovaní ADVIGREEN | F34: Grant | G34: Celorepublikové | H34: neuvedené | I34: 80 % | J34: 50 000 Kč | L34: priebežne | M34: Priebežná | N34: =IF(K34="",M34,IF(K34<Súhrn!$B$3,"Po uzávierke",IF(M34="Očakávaná","Očakávaná",IF(K34-Súhrn!$B$3<=14,"Končí do 14 dní","Otvorená")))) -> Priebežná | O34: =IF(K34="","",K34-Súhrn!$B$3) | P34: Stredná | Q34: Dotácia pre poľnohospodárskych poradcov. | R34: tvoj zoznam
A35: 82 | B35: Tvoj zoznam | C35: Národní rozvojová banka | D35: Zvýhodnený úver Energ (Praha) | E35: Firmy v Prahe | F35: Zvýhodnený úver | G35: Regionálne | H35: 129 856 463 Kč | I35: neuvedené | J35: 60 000 000 Kč | L35: priebežne | M35: Priebežná | N35: =IF(K35="",M35,IF(K35<Súhrn!$B$3,"Po uzávierke",IF(M35="Očakávaná","Očakávaná",IF(K35-Súhrn!$B$3<=14,"Končí do 14 dní","Otvorená")))) -> Priebežná | O35: =IF(K35="","",K35-Súhrn!$B$3) | P35: Stredná | Q35: Záznam z 2021 – overiť, či beží. | R35: tvoj zoznam
A36: 85 | B36: Tvoj zoznam | C36: SZP 2023–2027 | D36: Podpora poradenstva – a) individuálne poradenstvo (záznam 2023) | E36: Poradcovia certifikovaní ADVIGREEN | F36: Grant | G36: Celorepublikové | H36: 241 015 304 Kč | I36: 80 % | J36: 50 000 Kč | L36: priebežne do vyčerpania | M36: Priebežná | N36: =IF(K36="",M36,IF(K36<Súhrn!$B$3,"Po uzávierke",IF(M36="Očakávaná","Očakávaná",IF(K36-Súhrn!$B$3<=14,"Končí do 14 dní","Otvorená")))) -> Priebežná | O36: =IF(K36="","",K36-Súhrn!$B$3) | P36: Stredná | Q36: Duplicita k záznamu z 11. 9. 2026 (starší záznam). | R36: tvoj zoznam
A37: 86 | B37: Tvoj zoznam | C37: Národní rozvojová banka | D37: Nová ELENA (EPC projekty) | E37: Verejný sektor, firmy | F37: Iné mechanizmy | G37: Celorepublikové | H37: neuvedené | I37: 90 % | J37: neuvedené | L37: priebežne | M37: Priebežná | N37: =IF(K37="",M37,IF(K37<Súhrn!$B$3,"Po uzávierke",IF(M37="Očakávaná","Očakávaná",IF(K37-Súhrn!$B$3<=14,"Končí do 14 dní","Otvorená")))) -> Priebežná | O37: =IF(K37="","",K37-Súhrn!$B$3) | P37: Stredná | R37: tvoj zoznam
A38: 87 | B38: Tvoj zoznam | C38: Národní rozvojová banka | D38: ENERG (Praha) | E38: Firmy v Prahe | F38: Zvýhodnený úver | G38: Regionálne | H38: 90 000 000 Kč | I38: neuvedené | J38: 60 000 000 Kč | L38: priebežne | M38: Priebežná | N38: =IF(K38="",M38,IF(K38<Súhrn!$B$3,"Po uzávierke",IF(M38="Očakávaná","Očakávaná",IF(K38-Súhrn!$B$3<=14,"Končí do 14 dní","Otvorená")))) -> Priebežná | O38: =IF(K38="","",K38-Súhrn!$B$3) | P38: Stredná | Q38: Záznam z 2021 – overiť, či beží. | R38: tvoj zoznam
A39: 92 | B39: Tvoj zoznam | C39: SZP 2023–2027 | D39: 54.78 Podpora poradenstva – záměry b)–f) | E39: Poradcovia, vzdelávacie subjekty, výskum | F39: Grant | G39: Celorepublikové | H39: €9 994 000 (v zdroji; asi Kč) | I39: 100 % | J39: 4 800 000 (v zdroji €; asi Kč) | L39: priebežne do vyčerpania | M39: Očakávaná | N39: =IF(K39="",M39,IF(K39<Súhrn!$B$3,"Po uzávierke",IF(M39="Očakávaná","Očakávaná",IF(K39-Súhrn!$B$3<=14,"Končí do 14 dní","Otvorená")))) -> Očakávaná | O39: =IF(K39="","",K39-Súhrn!$B$3) | P39: Stredná | Q39: Mena v zdroji pravdepodobne chybná. | R39: tvoj zoznam
A40: 93 | B40: Tvoj zoznam | C40: OP Doprava | D40: 48. výzva – bežné dobíjacie stanice v obciach | E40: Vlastníci/správcovia infraštruktúry | F40: Grant | G40: Celorepublikové | H40: 70 000 000 Kč | I40: 80 % | J40: neuvedené | L40: vyhlásenie 12/2026, koniec 03/2027 | M40: Očakávaná | N40: =IF(K40="",M40,IF(K40<Súhrn!$B$3,"Po uzávierke",IF(M40="Očakávaná","Očakávaná",IF(K40-Súhrn!$B$3<=14,"Končí do 14 dní","Otvorená")))) -> Očakávaná | O40: =IF(K40="","",K40-Súhrn!$B$3) | P40: Stredná | Q40: Min. 20 dobíjacích bodov. | R40: tvoj zoznam
...

Sheet Legenda
A1: Čo je v zošite
A2: Výzvy | B2: 116 výziev: 105 z tvojho zoznamu + 11 doplnkov z webu, ktoré v zozname chýbali. Zoradené: najprv tie, na ktoré sa dá podať, podľa relevancie a uzávierky; stĺpec ID = poradie v zdroji.
A3: Zdroj | B3: „Tvoj zoznam“ = údaje prevzaté z tvojho zoznamu (neoverené proti poskytovateľom). „Doplnok (web)“ = nájdené vyhľadávaním 25. 9. 2026; odkaz v stĺpci Overenie.
A4: Stav k dátumu | B4: Vzorec z Uzávierky a dátumu v Súhrn!B3: Po uzávierke / Končí do 14 dní / Otvorená; bez dátumu sa preberá Status v zdroji (Priebežná, Očakávaná).
A5: Relevancia | B5: Môj odhad pre komerčné grantové poradenstvo v ČR: Vysoká = široký okruh klientov, rozumný termín a objem; Nízka = medzinárodné konzorciá, obrana, infraštruktúra, tendre, nadácie s malými sumami. Dá sa prepísať (rozbaľovací zoznam).
A6: Sumy | B6: Alokácia a max. dotácia sú text tak, ako v zdroji (Kč aj €); kde mena v zdroji vyzerá chybne, je to v poznámke.
A7: Upozornenia | B7: Stránka optak.gov.cz bola z prostredia nedostupná; doplnky OP TAK, IROP, NRB a SZIF sú z výsledkov vyhľadávania – pred ponukou klientovi overiť u poskytovateľa.
A8: Nepridané (už uzavreté) | B8: OP TAK Digitální podnik I (18. 2. 2026) a II (17. 4. 2026), Inovace IV (20. 2. 2026), Potenciál III (17. 2. 2026), NRB Expanze (pozastavené od 10. 8. 2026), EDIH II (25. 5. 2026), TA ČR TREND podprogram 2 (v 2026 sa nevyhlási).
A9: Sledovať | B9: Nová výzva OP TAK Úspory energie (plánovaná na 2026, termín neznámy); ďalšie kolo Digitální podnik (pre ERP/Odoo najdôležitejšie) – nenašiel som.
